<?xml version="1.0" ?>
<robot name="Arctos" xmlns:xacro="http://www.ros.org/wiki/xacro">

<xacro:include filename="$(find Arctos_description)/urdf/materials.xacro" />
<xacro:include filename="$(find Arctos_description)/urdf/Arctos.trans" />
<xacro:include filename="$(find Arctos_description)/urdf/Arctos.gazebo" />
<link name="base_link">
  <inertial>
    <origin xyz="2.8269170606611176e-07 0.042242089973694066 0.05486158680185389" rpy="0 0 0"/>
    <mass value="27.88896095763374"/>
    <inertia ixx="0.142501" iyy="0.083035" izz="0.16612" ixy="-1e-06" iyz="-0.001774" ixz="0.0"/>
  </inertial>
  <visual>
    <origin xyz="0 0 0" rpy="0 0 0"/>
    <geometry>
      <mesh filename="package://Arctos_description/meshes/base_link.stl" scale="0.001 0.001 0.001"/>
    </geometry>
    <material name="silver"/>
  </visual>
  <collision>
    <origin xyz="0 0 0" rpy="0 0 0"/>
    <geometry>
      <mesh filename="package://Arctos_description/meshes/base_link.stl" scale="0.001 0.001 0.001"/>
    </geometry>
  </collision>
</link>

<link name="J1_1">
  <inertial>
    <origin xyz="-1.2969016003578023e-08 -0.0046595914386929164 0.06093214652494226" rpy="0 0 0"/>
    <mass value="15.113319762308254"/>
    <inertia ixx="0.07326" iyy="0.084237" izz="0.070775" ixy="-0.0" iyz="0.002944" ixz="-0.0"/>
  </inertial>
  <visual>
    <origin xyz="-0.0 -0.023029 -0.111" rpy="0 0 0"/>
    <geometry>
      <mesh filename="package://Arctos_description/meshes/J1_1.stl" scale="0.001 0.001 0.001"/>
    </geometry>
    <material name="silver"/>
  </visual>
  <collision>
    <origin xyz="-0.0 -0.023029 -0.111" rpy="0 0 0"/>
    <geometry>
      <mesh filename="package://Arctos_description/meshes/J1_1.stl" scale="0.001 0.001 0.001"/>
    </geometry>
  </collision>
</link>

<link name="J2_1">
  <inertial>
    <origin xyz="-0.0570500292196927 0.006692178790930273 0.06182090814203128" rpy="0 0 0"/>
    <mass value="17.860862530176735"/>
    <inertia ixx="0.172429" iyy="0.185732" izz="0.054099" ixy="0.0" iyz="-0.009489" ixz="0.0"/>
  </inertial>
  <visual>
    <origin xyz="-0.05713 -0.002855 -0.28806" rpy="0 0 0"/>
    <geometry>
      <mesh filename="package://Arctos_description/meshes/J2_1.stl" scale="0.001 0.001 0.001"/>
    </geometry>
    <material name="silver"/>
  </visual>
  <collision>
    <origin xyz="-0.05713 -0.002855 -0.28806" rpy="0 0 0"/>
    <geometry>
      <mesh filename="package://Arctos_description/meshes/J2_1.stl" scale="0.001 0.001 0.001"/>
    </geometry>
  </collision>
</link>

<link name="J3_1">
  <inertial>
    <origin xyz="-0.04203696709554858 -0.037767013468914694 0.009992291463018832" rpy="0 0 0"/>
    <mass value="8.761133641193867"/>
    <inertia ixx="0.028147" iyy="0.011365" izz="0.026007" ixy="-0.000571" iyz="0.003914" ixz="0.000103"/>
  </inertial>
  <visual>
    <origin xyz="-0.04313 -0.003782 -0.548929" rpy="0 0 0"/>
    <geometry>
      <mesh filename="package://Arctos_description/meshes/J3_1.stl" scale="0.001 0.001 0.001"/>
    </geometry>
    <material name="silver"/>
  </visual>
  <collision>
    <origin xyz="-0.04313 -0.003782 -0.548929" rpy="0 0 0"/>
    <geometry>
      <mesh filename="package://Arctos_description/meshes/J3_1.stl" scale="0.001 0.001 0.001"/>
    </geometry>
  </collision>
</link>

<link name="J4_1">
  <inertial>
    <origin xyz="-0.0001619446675095186 -0.04851842997750348 -0.000892639082643365" rpy="0 0 0"/>
    <mass value="4.632994870218515"/>
    <inertia ixx="0.017799" iyy="0.010651" izz="0.023098" ixy="0.0" iyz="-0.000142" ixz="-0.0"/>
  </inertial>
  <visual>
    <origin xyz="0.001709 0.121908 -0.570126" rpy="0 0 0"/>
    <geometry>
      <mesh filename="package://Arctos_description/meshes/J4_1.stl" scale="0.001 0.001 0.001"/>
    </geometry>
    <material name="silver"/>
  </visual>
  <collision>
    <origin xyz="0.001709 0.121908 -0.570126" rpy="0 0 0"/>
    <geometry>
      <mesh filename="package://Arctos_description/meshes/J4_1.stl" scale="0.001 0.001 0.001"/>
    </geometry>
  </collision>
</link>

<link name="J5_1">
  <inertial>
    <origin xyz="0.04018140689948157 -0.0168114160506172 7.445309645581766e-06" rpy="0 0 0"/>
    <mass value="0.9556926931376224"/>
    <inertia ixx="0.0016" iyy="0.000788" izz="0.00136" ixy="2e-06" iyz="-1e-06" ixz="0.0"/>
  </inertial>
  <visual>
    <origin xyz="0.04199 0.254971 -0.568148" rpy="0 0 0"/>
    <geometry>
      <mesh filename="package://Arctos_description/meshes/J5_1.stl" scale="0.001 0.001 0.001"/>
    </geometry>
    <material name="silver"/>
  </visual>
  <collision>
    <origin xyz="0.04199 0.254971 -0.568148" rpy="0 0 0"/>
    <geometry>
      <mesh filename="package://Arctos_description/meshes/J5_1.stl" scale="0.001 0.001 0.001"/>
    </geometry>
  </collision>
</link>

<link name="J6_1">
  <inertial>
    <origin xyz="0.0011602471936715398 -0.004888221693008177 2.1744784393318284e-05" rpy="0 0 0"/>
    <mass value="0.20362461815315086"/>
    <inertia ixx="0.000169" iyy="0.000326" izz="0.000169" ixy="-0.0" iyz="0.0" ixz="-0.0"/>
  </inertial>
  <visual>
    <origin xyz="0.00303 0.313516 -0.568106" rpy="0 0 0"/>
    <geometry>
      <mesh filename="package://Arctos_description/meshes/J6_1.stl" scale="0.001 0.001 0.001"/>
    </geometry>
    <material name="silver"/>
  </visual>
  <collision>
    <origin xyz="0.00303 0.313516 -0.568106" rpy="0 0 0"/>
    <geometry>
      <mesh filename="package://Arctos_description/meshes/J6_1.stl" scale="0.001 0.001 0.001"/>
    </geometry>
  </collision>
</link>

<joint name="Revolute 1" type="continuous">
  <origin xyz="0.0 0.023029 0.111" rpy="0 0 0"/>
  <parent link="base_link"/>
  <child link="J1_1"/>
  <axis xyz="-0.0 0.0 1.0"/>
</joint>

<joint name="Revolute 2" type="continuous">
  <origin xyz="0.05713 -0.020174 0.17706" rpy="0 0 0"/>
  <parent link="J1_1"/>
  <child link="J2_1"/>
  <axis xyz="1.0 -0.0 0.0"/>
</joint>

<joint name="Revolute 3" type="continuous">
  <origin xyz="-0.014 0.000927 0.260869" rpy="0 0 0"/>
  <parent link="J2_1"/>
  <child link="J3_1"/>
  <axis xyz="-1.0 -0.0 -0.0"/>
</joint>

<joint name="Revolute 4" type="continuous">
  <origin xyz="-0.044839 -0.12569 0.021197" rpy="0 0 0"/>
  <parent link="J3_1"/>
  <child link="J4_1"/>
  <axis xyz="-0.0 1.0 0.0"/>
</joint>

<joint name="Revolute 5" type="continuous">
  <origin xyz="-0.040281 -0.133063 -0.001978" rpy="0 0 0"/>
  <parent link="J4_1"/>
  <child link="J5_1"/>
  <axis xyz="1.0 0.0 0.0"/>
</joint>

<joint name="Revolute 6" type="continuous">
  <origin xyz="0.03896 -0.058545 -4.2e-05" rpy="0 0 0"/>
  <parent link="J5_1"/>
  <child link="J6_1"/>
  <axis xyz="0.0 -1.0 -0.0"/>
</joint>

</robot>
